Workbook

Sheet Params
A1: PARÀMETRES V2H — SIMULACIÓ DIÀRIA 8760h (v7)
A2: Paràmetre | B2: Valor | C2: Unitat
A3: C_bat | B3: 40 | C3: kWh
A4: SOC_max | B4: 0.9
A5: SOC_min | B5: 0.3
A6: P_carg | B6: 7.4 | C6: kW
A7: P_desc | B7: 7.4 | C7: kW
A8: eta_carg | B8: 0.95
A9: eta_desc | B9: 0.95
A10: c_esp | B10: 0.18 | C10: kWh/km
A11: d_lab | B11: 40 | C11: km
A12: d_fds | B12: 30 | C12: km
A13: t_sort_lab | B13: 7 | C13: h
A14: t_arr_lab | B14: 19 | C14: h
A15: t_sort_fds | B15: 10 | C15: h
A16: t_arr_fds | B16: 15 | C16: h
A17: FV_kWp | B17: 4.6 | C17: kWp
A18: Habitatge | B18: Gurb
A19: Escenari | B19: 1
A20: SOC_reserva_lab | B20: =B5+B11*B10/(2*B3)+0.1
A21: SOC_reserva_fds | B21: =B5+B12*B10/(2*B3)+0.1

Sheet Sim8760
A1: SIMULACIÓ HORÀRIA ANUAL — 8760 HORES, SOC ENCADENAT
A3: # | B3: Data | C3: Hora | D3: FDS? | E3: δ(t) | F3: P_llar kWh | G3: P_FV kWh | H3: P_net kWh | I3: Acció | J3: E_carg kWh | K3: E_V2H kWh | L3: E_xarxa kWh | M3: SOC % | N3: Tarifa €/kWh | O3: Estalvi € | P3: SOC_limit
A4: 1 | B4: 01/01 | C4: 0 | D4: 0 | E4: =IF(D4=1, IF(OR(C4<10, C4>=15),1,0), IF(OR(C4<7, C4>=18),1,0)) | F4: 4.107 | G4: =0*8 | H4: =F4-G4 | I4: =IF(E4=0,"Fora",IF(AND(H4<0,M4<0.9),"Carg FV",IF(AND(H4>0,M4>0.3),"V2H",IF(M4<0.9,"Carg xar","Stby")))) | J4: =IF(OR(I4="Carg FV",I4="Carg xar"),MIN(IF(I4="Carg FV",ABS(H4),7.4),7.4,MAX(0,(0.9-M4)*40)*0.95),0) | K4: =IF(I4="V2H",MIN(MAX(0,H4),7.4,MAX(0,(M4-P4)*40)*0.95),0) | L4: =IF(E4=0, 0, MAX(0, H4-K4)) | M4: 0.9 | N4: 0.09 | O4: =K4*N4
A5: 2 | B5: 01/01 | C5: 1 | D5: 0 | E5: =IF(D5=1, IF(OR(C5<10, C5>=15),1,0), IF(OR(C5<7, C5>=18),1,0)) | F5: 3.933 | G5: =0*8 | H5: =F5-G5 | I5: =IF(E5=0,"Fora",IF(E4=0,"Carg xar",IF(H5<0,IF(M5<0.9,"Carg FV","Stby"),IF(M5>P5,"V2H",IF(M5<0.9,"Carg xar","Stby"))))) | J5: =IF(OR(I5="Carg FV",I5="Carg xar"),MIN(IF(I5="Carg FV",ABS(H5),7.4),7.4,MAX(0,(0.9-M5)*40)*0.95),0) | K5: =IF(I5="V2H",MIN(MAX(0,H5),7.4,MAX(0,(M5-P5)*40)*0.95),0) | L5: =IF(E5=0,0,MAX(0,H5-K5)) | M5: =M4+J4/40-IF(I4="V2H",K4/(0.95*40),0)-IF(E5=0,IF(E4=1,IF(D5=1,30,40)*0.18/(2*40),0),0)-IF(E5=1,IF(E4=0,IF(D5=1,30,40)*0.18/(2*40),0),0) | N5: 0.09 | O5: =K5*N5 | P5: =IF(E5=0,0.3,IF(D5=1,IF(C5>=Params!$B$13-3,IF(C5<Params!$B$13,Params!$B$20,0.3),0.3),IF(C5>=Params!$B$15-3,IF(C5<Params!$B$15,Params!$B$21,0.3),0.3)))
A6: 3 | B6: 01/01 | C6: 2 | D6: 0 | E6: =IF(D6=1, IF(OR(C6<10, C6>=15),1,0), IF(OR(C6<7, C6>=18),1,0)) | F6: 4.504 | G6: =0*8 | H6: =F6-G6 | I6: =IF(E6=0,"Fora",IF(E5=0,"Carg xar",IF(H6<0,IF(M6<0.9,"Carg FV","Stby"),IF(M6>P6,"V2H",IF(M6<0.9,"Carg xar","Stby"))))) | J6: =IF(OR(I6="Carg FV",I6="Carg xar"),MIN(IF(I6="Carg FV",ABS(H6),7.4),7.4,MAX(0,(0.9-M6)*40)*0.95),0) | K6: =IF(I6="V2H",MIN(MAX(0,H6),7.4,MAX(0,(M6-P6)*40)*0.95),0) | L6: =IF(E6=0,0,MAX(0,H6-K6)) | M6: =M5+J5/40-IF(I5="V2H",K5/(0.95*40),0)-IF(E6=0,IF(E5=1,IF(D6=1,30,40)*0.18/(2*40),0),0)-IF(E6=1,IF(E5=0,IF(D6=1,30,40)*0.18/(2*40),0),0) | N6: 0.09 | O6: =K6*N6 | P6: =IF(E6=0,0.3,IF(D6=1,IF(C6>=Params!$B$13-3,IF(C6<Params!$B$13,Params!$B$20,0.3),0.3),IF(C6>=Params!$B$15-3,IF(C6<Params!$B$15,Params!$B$21,0.3),0.3)))
A7: 4 | B7: 01/01 | C7: 3 | D7: 0 | E7: =IF(D7=1, IF(OR(C7<10, C7>=15),1,0), IF(OR(C7<7, C7>=18),1,0)) | F7: 4.048 | G7: =0*8 | H7: =F7-G7 | I7: =IF(E7=0,"Fora",IF(E6=0,"Carg xar",IF(H7<0,IF(M7<0.9,"Carg FV","Stby"),IF(M7>P7,"V2H",IF(M7<0.9,"Carg xar","Stby"))))) | J7: =IF(OR(I7="Carg FV",I7="Carg xar"),MIN(IF(I7="Carg FV",ABS(H7),7.4),7.4,MAX(0,(0.9-M7)*40)*0.95),0) | K7: =IF(I7="V2H",MIN(MAX(0,H7),7.4,MAX(0,(M7-P7)*40)*0.95),0) | L7: =IF(E7=0,0,MAX(0,H7-K7)) | M7: =M6+J6/40-IF(I6="V2H",K6/(0.95*40),0)-IF(E7=0,IF(E6=1,IF(D7=1,30,40)*0.18/(2*40),0),0)-IF(E7=1,IF(E6=0,IF(D7=1,30,40)*0.18/(2*40),0),0) | N7: 0.09 | O7: =K7*N7 | P7: =IF(E7=0,0.3,IF(D7=1,IF(C7>=Params!$B$13-3,IF(C7<Params!$B$13,Params!$B$20,0.3),0.3),IF(C7>=Params!$B$15-3,IF(C7<Params!$B$15,Params!$B$21,0.3),0.3)))
A8: 5 | B8: 01/01 | C8: 4 | D8: 0 | E8: =IF(D8=1, IF(OR(C8<10, C8>=15),1,0), IF(OR(C8<7, C8>=18),1,0)) | F8: 3.944 | G8: =0*8 | H8: =F8-G8 | I8: =IF(E8=0,"Fora",IF(E7=0,"Carg xar",IF(H8<0,IF(M8<0.9,"Carg FV","Stby"),IF(M8>P8,"V2H",IF(M8<0.9,"Carg xar","Stby"))))) | J8: =IF(OR(I8="Carg FV",I8="Carg xar"),MIN(IF(I8="Carg FV",ABS(H8),7.4),7.4,MAX(0,(0.9-M8)*40)*0.95),0) | K8: =IF(I8="V2H",MIN(MAX(0,H8),7.4,MAX(0,(M8-P8)*40)*0.95),0) | L8: =IF(E8=0,0,MAX(0,H8-K8)) | M8: =M7+J7/40-IF(I7="V2H",K7/(0.95*40),0)-IF(E8=0,IF(E7=1,IF(D8=1,30,40)*0.18/(2*40),0),0)-IF(E8=1,IF(E7=0,IF(D8=1,30,40)*0.18/(2*40),0),0) | N8: 0.09 | O8: =K8*N8 | P8: =IF(E8=0,0.3,IF(D8=1,IF(C8>=Params!$B$13-3,IF(C8<Params!$B$13,Params!$B$20,0.3),0.3),IF(C8>=Params!$B$15-3,IF(C8<Params!$B$15,Params!$B$21,0.3),0.3)))
A9: 6 | B9: 01/01 | C9: 5 | D9: 0 | E9: =IF(D9=1, IF(OR(C9<10, C9>=15),1,0), IF(OR(C9<7, C9>=18),1,0)) | F9: 3.89 | G9: =0*8 | H9: =F9-G9 | I9: =IF(E9=0,"Fora",IF(E8=0,"Carg xar",IF(H9<0,IF(M9<0.9,"Carg FV","Stby"),IF(M9>P9,"V2H",IF(M9<0.9,"Carg xar","Stby"))))) | J9: =IF(OR(I9="Carg FV",I9="Carg xar"),MIN(IF(I9="Carg FV",ABS(H9),7.4),7.4,MAX(0,(0.9-M9)*40)*0.95),0) | K9: =IF(I9="V2H",MIN(MAX(0,H9),7.4,MAX(0,(M9-P9)*40)*0.95),0) | L9: =IF(E9=0,0,MAX(0,H9-K9)) | M9: =M8+J8/40-IF(I8="V2H",K8/(0.95*40),0)-IF(E9=0,IF(E8=1,IF(D9=1,30,40)*0.18/(2*40),0),0)-IF(E9=1,IF(E8=0,IF(D9=1,30,40)*0.18/(2*40),0),0) | N9: 0.09 | O9: =K9*N9 | P9: =IF(E9=0,0.3,IF(D9=1,IF(C9>=Params!$B$13-3,IF(C9<Params!$B$13,Params!$B$20,0.3),0.3),IF(C9>=Params!$B$15-3,IF(C9<Params!$B$15,Params!$B$21,0.3),0.3)))
A10: 7 | B10: 01/01 | C10: 6 | D10: 0 | E10: =IF(D10=1, IF(OR(C10<10, C10>=15),1,0), IF(OR(C10<7, C10>=18),1,0)) | F10: 3.465 | G10: =0*8 | H10: =F10-G10 | I10: =IF(E10=0,"Fora",IF(E9=0,"Carg xar",IF(H10<0,IF(M10<0.9,"Carg FV","Stby"),IF(M10>P10,"V2H",IF(M10<0.9,"Carg xar","Stby"))))) | J10: =IF(OR(I10="Carg FV",I10="Carg xar"),MIN(IF(I10="Carg FV",ABS(H10),7.4),7.4,MAX(0,(0.9-M10)*40)*0.95),0) | K10: =IF(I10="V2H",MIN(MAX(0,H10),7.4,MAX(0,(M10-P10)*40)*0.95),0) | L10: =IF(E10=0,0,MAX(0,H10-K10)) | M10: =M9+J9/40-IF(I9="V2H",K9/(0.95*40),0)-IF(E10=0,IF(E9=1,IF(D10=1,30,40)*0.18/(2*40),0),0)-IF(E10=1,IF(E9=0,IF(D10=1,30,40)*0.18/(2*40),0),0) | N10: 0.09 | O10: =K10*N10 | P10: =IF(E10=0,0.3,IF(D10=1,IF(C10>=Params!$B$13-3,IF(C10<Params!$B$13,Params!$B$20,0.3),0.3),IF(C10>=Params!$B$15-3,IF(C10<Params!$B$15,Params!$B$21,0.3),0.3)))
A11: 8 | B11: 01/01 | C11: 7 | D11: 0 | E11: =IF(D11=1, IF(OR(C11<10, C11>=15),1,0), IF(OR(C11<7, C11>=18),1,0)) | F11: 0.104 | G11: =0*8 | H11: =F11-G11 | I11: =IF(E11=0,"Fora",IF(E10=0,"Carg xar",IF(H11<0,IF(M11<0.9,"Carg FV","Stby"),IF(M11>P11,"V2H",IF(M11<0.9,"Carg xar","Stby"))))) | J11: =IF(OR(I11="Carg FV",I11="Carg xar"),MIN(IF(I11="Carg FV",ABS(H11),7.4),7.4,MAX(0,(0.9-M11)*40)*0.95),0) | K11: =IF(I11="V2H",MIN(MAX(0,H11),7.4,MAX(0,(M11-P11)*40)*0.95),0) | L11: =IF(E11=0,0,MAX(0,H11-K11)) | M11: =M10+J10/40-IF(I10="V2H",K10/(0.95*40),0)-IF(E11=0,IF(E10=1,IF(D11=1,30,40)*0.18/(2*40),0),0)-IF(E11=1,IF(E10=0,IF(D11=1,30,40)*0.18/(2*40),0),0) | N11: 0.09 | O11: =K11*N11 | P11: =IF(E11=0,0.3,IF(D11=1,IF(C11>=Params!$B$13-3,IF(C11<Params!$B$13,Params!$B$20,0.3),0.3),IF(C11>=Params!$B$15-3,IF(C11<Params!$B$15,Params!$B$21,0.3),0.3)))
A12: 9 | B12: 01/01 | C12: 8 | D12: 0 | E12: =IF(D12=1, IF(OR(C12<10, C12>=15),1,0), IF(OR(C12<7, C12>=18),1,0)) | F12: 0.073 | G12: =0.05*8 | H12: =F12-G12 | I12: =IF(E12=0,"Fora",IF(E11=0,"Carg xar",IF(H12<0,IF(M12<0.9,"Carg FV","Stby"),IF(M12>P12,"V2H",IF(M12<0.9,"Carg xar","Stby"))))) | J12: =IF(OR(I12="Carg FV",I12="Carg xar"),MIN(IF(I12="Carg FV",ABS(H12),7.4),7.4,MAX(0,(0.9-M12)*40)*0.95),0) | K12: =IF(I12="V2H",MIN(MAX(0,H12),7.4,MAX(0,(M12-P12)*40)*0.95),0) | L12: =IF(E12=0,0,MAX(0,H12-K12)) | M12: =M11+J11/40-IF(I11="V2H",K11/(0.95*40),0)-IF(E12=0,IF(E11=1,IF(D12=1,30,40)*0.18/(2*40),0),0)-IF(E12=1,IF(E11=0,IF(D12=1,30,40)*0.18/(2*40),0),0) | N12: 0.15 | O12: =K12*N12 | P12: =IF(E12=0,0.3,IF(D12=1,IF(C12>=Params!$B$13-3,IF(C12<Params!$B$13,Params!$B$20,0.3),0.3),IF(C12>=Params!$B$15-3,IF(C12<Params!$B$15,Params!$B$21,0.3),0.3)))
A13: 10 | B13: 01/01 | C13: 9 | D13: 0 | E13: =IF(D13=1, IF(OR(C13<10, C13>=15),1,0), IF(OR(C13<7, C13>=18),1,0)) | F13: 0.084 | G13: =0.18*8 | H13: =F13-G13 | I13: =IF(E13=0,"Fora",IF(E12=0,"Carg xar",IF(H13<0,IF(M13<0.9,"Carg FV","Stby"),IF(M13>P13,"V2H",IF(M13<0.9,"Carg xar","Stby"))))) | J13: =IF(OR(I13="Carg FV",I13="Carg xar"),MIN(IF(I13="Carg FV",ABS(H13),7.4),7.4,MAX(0,(0.9-M13)*40)*0.95),0) | K13: =IF(I13="V2H",MIN(MAX(0,H13),7.4,MAX(0,(M13-P13)*40)*0.95),0) | L13: =IF(E13=0,0,MAX(0,H13-K13)) | M13: =M12+J12/40-IF(I12="V2H",K12/(0.95*40),0)-IF(E13=0,IF(E12=1,IF(D13=1,30,40)*0.18/(2*40),0),0)-IF(E13=1,IF(E12=0,IF(D13=1,30,40)*0.18/(2*40),0),0) | N13: 0.15 | O13: =K13*N13 | P13: =IF(E13=0,0.3,IF(D13=1,IF(C13>=Params!$B$13-3,IF(C13<Params!$B$13,Params!$B$20,0.3),0.3),IF(C13>=Params!$B$15-3,IF(C13<Params!$B$15,Params!$B$21,0.3),0.3)))
A14: 11 | B14: 01/01 | C14: 10 | D14: 0 | E14: =IF(D14=1, IF(OR(C14<10, C14>=15),1,0), IF(OR(C14<7, C14>=18),1,0)) | F14: 1.092 | G14: =0.38*8 | H14: =F14-G14 | I14: =IF(E14=0,"Fora",IF(E13=0,"Carg xar",IF(H14<0,IF(M14<0.9,"Carg FV","Stby"),IF(M14>P14,"V2H",IF(M14<0.9,"Carg xar","Stby"))))) | J14: =IF(OR(I14="Carg FV",I14="Carg xar"),MIN(IF(I14="Carg FV",ABS(H14),7.4),7.4,MAX(0,(0.9-M14)*40)*0.95),0) | K14: =IF(I14="V2H",MIN(MAX(0,H14),7.4,MAX(0,(M14-P14)*40)*0.95),0) | L14: =IF(E14=0,0,MAX(0,H14-K14)) | M14: =M13+J13/40-IF(I13="V2H",K13/(0.95*40),0)-IF(E14=0,IF(E13=1,IF(D14=1,30,40)*0.18/(2*40),0),0)-IF(E14=1,IF(E13=0,IF(D14=1,30,40)*0.18/(2*40),0),0) | N14: 0.2 | O14: =K14*N14 | P14: =IF(E14=0,0.3,IF(D14=1,IF(C14>=Params!$B$13-3,IF(C14<Params!$B$13,Params!$B$20,0.3),0.3),IF(C14>=Params!$B$15-3,IF(C14<Params!$B$15,Params!$B$21,0.3),0.3)))
A15: 12 | B15: 01/01 | C15: 11 | D15: 0 | E15: =IF(D15=1, IF(OR(C15<10, C15>=15),1,0), IF(OR(C15<7, C15>=18),1,0)) | F15: 2.791 | G15: =0.52*8 | H15: =F15-G15 | I15: =IF(E15=0,"Fora",IF(E14=0,"Carg xar",IF(H15<0,IF(M15<0.9,"Carg FV","Stby"),IF(M15>P15,"V2H",IF(M15<0.9,"Carg xar","Stby"))))) | J15: =IF(OR(I15="Carg FV",I15="Carg xar"),MIN(IF(I15="Carg FV",ABS(H15),7.4),7.4,MAX(0,(0.9-M15)*40)*0.95),0) | K15: =IF(I15="V2H",MIN(MAX(0,H15),7.4,MAX(0,(M15-P15)*40)*0.95),0) | L15: =IF(E15=0,0,MAX(0,H15-K15)) | M15: =M14+J14/40-IF(I14="V2H",K14/(0.95*40),0)-IF(E15=0,IF(E14=1,IF(D15=1,30,40)*0.18/(2*40),0),0)-IF(E15=1,IF(E14=0,IF(D15=1,30,40)*0.18/(2*40),0),0) | N15: 0.2 | O15: =K15*N15 | P15: =IF(E15=0,0.3,IF(D15=1,IF(C15>=Params!$B$13-3,IF(C15<Params!$B$13,Params!$B$20,0.3),0.3),IF(C15>=Params!$B$15-3,IF(C15<Params!$B$15,Params!$B$21,0.3),0.3)))
A16: 13 | B16: 01/01 | C16: 12 | D16: 0 | E16: =IF(D16=1, IF(OR(C16<10, C16>=15),1,0), IF(OR(C16<7, C16>=18),1,0)) | F16: 2.784 | G16: =0.58*8 | H16: =F16-G16 | I16: =IF(E16=0,"Fora",IF(E15=0,"Carg xar",IF(H16<0,IF(M16<0.9,"Carg FV","Stby"),IF(M16>P16,"V2H",IF(M16<0.9,"Carg xar","Stby"))))) | J16: =IF(OR(I16="Carg FV",I16="Carg xar"),MIN(IF(I16="Carg FV",ABS(H16),7.4),7.4,MAX(0,(0.9-M16)*40)*0.95),0) | K16: =IF(I16="V2H",MIN(MAX(0,H16),7.4,MAX(0,(M16-P16)*40)*0.95),0) | L16: =IF(E16=0,0,MAX(0,H16-K16)) | M16: =M15+J15/40-IF(I15="V2H",K15/(0.95*40),0)-IF(E16=0,IF(E15=1,IF(D16=1,30,40)*0.18/(2*40),0),0)-IF(E16=1,IF(E15=0,IF(D16=1,30,40)*0.18/(2*40),0),0) | N16: 0.2 | O16: =K16*N16 | P16: =IF(E16=0,0.3,IF(D16=1,IF(C16>=Params!$B$13-3,IF(C16<Params!$B$13,Params!$B$20,0.3),0.3),IF(C16>=Params!$B$15-3,IF(C16<Params!$B$15,Params!$B$21,0.3),0.3)))
A17: 14 | B17: 01/01 | C17: 13 | D17: 0 | E17: =IF(D17=1, IF(OR(C17<10, C17>=15),1,0), IF(OR(C17<7, C17>=18),1,0)) | F17: 1.773 | G17: =0.55*8 | H17: =F17-G17 | I17: =IF(E17=0,"Fora",IF(E16=0,"Carg xar",IF(H17<0,IF(M17<0.9,"Carg FV","Stby"),IF(M17>P17,"V2H",IF(M17<0.9,"Carg xar","Stby"))))) | J17: =IF(OR(I17="Carg FV",I17="Carg xar"),MIN(IF(I17="Carg FV",ABS(H17),7.4),7.4,MAX(0,(0.9-M17)*40)*0.95),0) | K17: =IF(I17="V2H",MIN(MAX(0,H17),7.4,MAX(0,(M17-P17)*40)*0.95),0) | L17: =IF(E17=0,0,MAX(0,H17-K17)) | M17: =M16+J16/40-IF(I16="V2H",K16/(0.95*40),0)-IF(E17=0,IF(E16=1,IF(D17=1,30,40)*0.18/(2*40),0),0)-IF(E17=1,IF(E16=0,IF(D17=1,30,40)*0.18/(2*40),0),0) | N17: 0.2 | O17: =K17*N17 | P17: =IF(E17=0,0.3,IF(D17=1,IF(C17>=Params!$B$13-3,IF(C17<Params!$B$13,Params!$B$20,0.3),0.3),IF(C17>=Params!$B$15-3,IF(C17<Params!$B$15,Params!$B$21,0.3),0.3)))
A18: 15 | B18: 01/01 | C18: 14 | D18: 0 | E18: =IF(D18=1, IF(OR(C18<10, C18>=15),1,0), IF(OR(C18<7, C18>=18),1,0)) | F18: 0 | G18: =0.42*8 | H18: =F18-G18 | I18: =IF(E18=0,"Fora",IF(E17=0,"Carg xar",IF(H18<0,IF(M18<0.9,"Carg FV","Stby"),IF(M18>P18,"V2H",IF(M18<0.9,"Carg xar","Stby"))))) | J18: =IF(OR(I18="Carg FV",I18="Carg xar"),MIN(IF(I18="Carg FV",ABS(H18),7.4),7.4,MAX(0,(0.9-M18)*40)*0.95),0) | K18: =IF(I18="V2H",MIN(MAX(0,H18),7.4,MAX(0,(M18-P18)*40)*0.95),0) | L18: =IF(E18=0,0,MAX(0,H18-K18)) | M18: =M17+J17/40-IF(I17="V2H",K17/(0.95*40),0)-IF(E18=0,IF(E17=1,IF(D18=1,30,40)*0.18/(2*40),0),0)-IF(E18=1,IF(E17=0,IF(D18=1,30,40)*0.18/(2*40),0),0) | N18: 0.15 | O18: =K18*N18 | P18: =IF(E18=0,0.3,IF(D18=1,IF(C18>=Params!$B$13-3,IF(C18<Params!$B$13,Params!$B$20,0.3),0.3),IF(C18>=Params!$B$15-3,IF(C18<Params!$B$15,Params!$B$21,0.3),0.3)))
A19: 16 | B19: 01/01 | C19: 15 | D19: 0 | E19: =IF(D19=1, IF(OR(C19<10, C19>=15),1,0), IF(OR(C19<7, C19>=18),1,0)) | F19: 0 | G19: =0.22*8 | H19: =F19-G19 | I19: =IF(E19=0,"Fora",IF(E18=0,"Carg xar",IF(H19<0,IF(M19<0.9,"Carg FV","Stby"),IF(M19>P19,"V2H",IF(M19<0.9,"Carg xar","Stby"))))) | J19: =IF(OR(I19="Carg FV",I19="Carg xar"),MIN(IF(I19="Carg FV",ABS(H19),7.4),7.4,MAX(0,(0.9-M19)*40)*0.95),0) | K19: =IF(I19="V2H",MIN(MAX(0,H19),7.4,MAX(0,(M19-P19)*40)*0.95),0) | L19: =IF(E19=0,0,MAX(0,H19-K19)) | M19: =M18+J18/40-IF(I18="V2H",K18/(0.95*40),0)-IF(E19=0,IF(E18=1,IF(D19=1,30,40)*0.18/(2*40),0),0)-IF(E19=1,IF(E18=0,IF(D19=1,30,40)*0.18/(2*40),0),0) | N19: 0.15 | O19: =K19*N19 | P19: =IF(E19=0,0.3,IF(D19=1,IF(C19>=Params!$B$13-3,IF(C19<Params!$B$13,Params!$B$20,0.3),0.3),IF(C19>=Params!$B$15-3,IF(C19<Params!$B$15,Params!$B$21,0.3),0.3)))
A20: 17 | B20: 01/01 | C20: 16 | D20: 0 | E20: =IF(D20=1, IF(OR(C20<10, C20>=15),1,0), IF(OR(C20<7, C20>=18),1,0)) | F20: 0.186 | G20: =0.05*8 | H20: =F20-G20 | I20: =IF(E20=0,"Fora",IF(E19=0,"Carg xar",IF(H20<0,IF(M20<0.9,"Carg FV","Stby"),IF(M20>P20,"V2H",IF(M20<0.9,"Carg xar","Stby"))))) | J20: =IF(OR(I20="Carg FV",I20="Carg xar"),MIN(IF(I20="Carg FV",ABS(H20),7.4),7.4,MAX(0,(0.9-M20)*40)*0.95),0) | K20: =IF(I20="V2H",MIN(MAX(0,H20),7.4,MAX(0,(M20-P20)*40)*0.95),0) | L20: =IF(E20=0,0,MAX(0,H20-K20)) | M20: =M19+J19/40-IF(I19="V2H",K19/(0.95*40),0)-IF(E20=0,IF(E19=1,IF(D20=1,30,40)*0.18/(2*40),0),0)-IF(E20=1,IF(E19=0,IF(D20=1,30,40)*0.18/(2*40),0),0) | N20: 0.15 | O20: =K20*N20 | P20: =IF(E20=0,0.3,IF(D20=1,IF(C20>=Params!$B$13-3,IF(C20<Params!$B$13,Params!$B$20,0.3),0.3),IF(C20>=Params!$B$15-3,IF(C20<Params!$B$15,Params!$B$21,0.3),0.3)))
A21: 18 | B21: 01/01 | C21: 17 | D21: 0 | E21: =IF(D21=1, IF(OR(C21<10, C21>=15),1,0), IF(OR(C21<7, C21>=18),1,0)) | F21: 0.455 | G21: =0*8 | H21: =F21-G21 | I21: =IF(E21=0,"Fora",IF(E20=0,"Carg xar",IF(H21<0,IF(M21<0.9,"Carg FV","Stby"),IF(M21>P21,"V2H",IF(M21<0.9,"Carg xar","Stby"))))) | J21: =IF(OR(I21="Carg FV",I21="Carg xar"),MIN(IF(I21="Carg FV",ABS(H21),7.4),7.4,MAX(0,(0.9-M21)*40)*0.95),0) | K21: =IF(I21="V2H",MIN(MAX(0,H21),7.4,MAX(0,(M21-P21)*40)*0.95),0) | L21: =IF(E21=0,0,MAX(0,H21-K21)) | M21: =M20+J20/40-IF(I20="V2H",K20/(0.95*40),0)-IF(E21=0,IF(E20=1,IF(D21=1,30,40)*0.18/(2*40),0),0)-IF(E21=1,IF(E20=0,IF(D21=1,30,40)*0.18/(2*40),0),0) | N21: 0.15 | O21: =K21*N21 | P21: =IF(E21=0,0.3,IF(D21=1,IF(C21>=Params!$B$13-3,IF(C21<Params!$B$13,Params!$B$20,0.3),0.3),IF(C21>=Params!$B$15-3,IF(C21<Params!$B$15,Params!$B$21,0.3),0.3)))
A22: 19 | B22: 01/01 | C22: 18 | D22: 0 | E22: =IF(D22=1, IF(OR(C22<10, C22>=15),1,0), IF(OR(C22<7, C22>=18),1,0)) | F22: 0.631 | G22: =0*8 | H22: =F22-G22 | I22: =IF(E22=0,"Fora",IF(E21=0,"Carg xar",IF(H22<0,IF(M22<0.9,"Carg FV","Stby"),IF(M22>P22,"V2H",IF(M22<0.9,"Carg xar","Stby"))))) | J22: =IF(OR(I22="Carg FV",I22="Carg xar"),MIN(IF(I22="Carg FV",ABS(H22),7.4),7.4,MAX(0,(0.9-M22)*40)*0.95),0) | K22: =IF(I22="V2H",MIN(MAX(0,H22),7.4,MAX(0,(M22-P22)*40)*0.95),0) | L22: =IF(E22=0,0,MAX(0,H22-K22)) | M22: =M21+J21/40-IF(I21="V2H",K21/(0.95*40),0)-IF(E22=0,IF(E21=1,IF(D22=1,30,40)*0.18/(2*40),0),0)-IF(E22=1,IF(E21=0,IF(D22=1,30,40)*0.18/(2*40),0),0) | N22: 0.2 | O22: =K22*N22 | P22: =IF(E22=0,0.3,IF(D22=1,IF(C22>=Params!$B$13-3,IF(C22<Params!$B$13,Params!$B$20,0.3),0.3),IF(C22>=Params!$B$15-3,IF(C22<Params!$B$15,Params!$B$21,0.3),0.3)))
A23: 20 | B23: 01/01 | C23: 19 | D23: 0 | E23: =IF(D23=1, IF(OR(C23<10, C23>=15),1,0), IF(OR(C23<7, C23>=18),1,0)) | F23: 4.779 | G23: =0*8 | H23: =F23-G23 | I23: =IF(E23=0,"Fora",IF(E22=0,"Carg xar",IF(H23<0,IF(M23<0.9,"Carg FV","Stby"),IF(M23>P23,"V2H",IF(M23<0.9,"Carg xar","Stby"))))) | J23: =IF(OR(I23="Carg FV",I23="Carg xar"),MIN(IF(I23="Carg FV",ABS(H23),7.4),7.4,MAX(0,(0.9-M23)*40)*0.95),0) | K23: =IF(I23="V2H",MIN(MAX(0,H23),7.4,MAX(0,(M23-P23)*40)*0.95),0) | L23: =IF(E23=0,0,MAX(0,H23-K23)) | M23: =M22+J22/40-IF(I22="V2H",K22/(0.95*40),0)-IF(E23=0,IF(E22=1,IF(D23=1,30,40)*0.18/(2*40),0),0)-IF(E23=1,IF(E22=0,IF(D23=1,30,40)*0.18/(2*40),0),0) | N23: 0.2 | O23: =K23*N23 | P23: =IF(E23=0,0.3,IF(D23=1,IF(C23>=Params!$B$13-3,IF(C23<Params!$B$13,Params!$B$20,0.3),0.3),IF(C23>=Params!$B$15-3,IF(C23<Params!$B$15,Params!$B$21,0.3),0.3)))
A24: 21 | B24: 01/01 | C24: 20 | D24: 0 | E24: =IF(D24=1, IF(OR(C24<10, C24>=15),1,0), IF(OR(C24<7, C24>=18),1,0)) | F24: 4.698 | G24: =0*8 | H24: =F24-G24 | I24: =IF(E24=0,"Fora",IF(E23=0,"Carg xar",IF(H24<0,IF(M24<0.9,"Carg FV","Stby"),IF(M24>P24,"V2H",IF(M24<0.9,"Carg xar","Stby"))))) | J24: =IF(OR(I24="Carg FV",I24="Carg xar"),MIN(IF(I24="Carg FV",ABS(H24),7.4),7.4,MAX(0,(0.9-M24)*40)*0.95),0) | K24: =IF(I24="V2H",MIN(MAX(0,H24),7.4,MAX(0,(M24-P24)*40)*0.95),0) | L24: =IF(E24=0,0,MAX(0,H24-K24)) | M24: =M23+J23/40-IF(I23="V2H",K23/(0.95*40),0)-IF(E24=0,IF(E23=1,IF(D24=1,30,40)*0.18/(2*40),0),0)-IF(E24=1,IF(E23=0,IF(D24=1,30,40)*0.18/(2*40),0),0) | N24: 0.2 | O24: =K24*N24 | P24: =IF(E24=0,0.3,IF(D24=1,IF(C24>=Params!$B$13-3,IF(C24<Params!$B$13,Params!$B$20,0.3),0.3),IF(C24>=Params!$B$15-3,IF(C24<Params!$B$15,Params!$B$21,0.3),0.3)))
A25: 22 | B25: 01/01 | C25: 21 | D25: 0 | E25: =IF(D25=1, IF(OR(C25<10, C25>=15),1,0), IF(OR(C25<7, C25>=18),1,0)) | F25: 4.136 | G25: =0*8 | H25: =F25-G25 | I25: =IF(E25=0,"Fora",IF(E24=0,"Carg xar",IF(H25<0,IF(M25<0.9,"Carg FV","Stby"),IF(M25>P25,"V2H",IF(M25<0.9,"Carg xar","Stby"))))) | J25: =IF(OR(I25="Carg FV",I25="Carg xar"),MIN(IF(I25="Carg FV",ABS(H25),7.4),7.4,MAX(0,(0.9-M25)*40)*0.95),0) | K25: =IF(I25="V2H",MIN(MAX(0,H25),7.4,MAX(0,(M25-P25)*40)*0.95),0) | L25: =IF(E25=0,0,MAX(0,H25-K25)) | M25: =M24+J24/40-IF(I24="V2H",K24/(0.95*40),0)-IF(E25=0,IF(E24=1,IF(D25=1,30,40)*0.18/(2*40),0),0)-IF(E25=1,IF(E24=0,IF(D25=1,30,40)*0.18/(2*40),0),0) | N25: 0.2 | O25: =K25*N25 | P25: =IF(E25=0,0.3,IF(D25=1,IF(C25>=Params!$B$13-3,IF(C25<Params!$B$13,Params!$B$20,0.3),0.3),IF(C25>=Params!$B$15-3,IF(C25<Params!$B$15,Params!$B$21,0.3),0.3)))
A26: 23 | B26: 01/01 | C26: 22 | D26: 0 | E26: =IF(D26=1, IF(OR(C26<10, C26>=15),1,0), IF(OR(C26<7, C26>=18),1,0)) | F26: 4.144 | G26: =0*8 | H26: =F26-G26 | I26: =IF(E26=0,"Fora",IF(E25=0,"Carg xar",IF(H26<0,IF(M26<0.9,"Carg FV","Stby"),IF(M26>P26,"V2H",IF(M26<0.9,"Carg xar","Stby"))))) | J26: =IF(OR(I26="Carg FV",I26="Carg xar"),MIN(IF(I26="Carg FV",ABS(H26),7.4),7.4,MAX(0,(0.9-M26)*40)*0.95),0) | K26: =IF(I26="V2H",MIN(MAX(0,H26),7.4,MAX(0,(M26-P26)*40)*0.95),0) | L26: =IF(E26=0,0,MAX(0,H26-K26)) | M26: =M25+J25/40-IF(I25="V2H",K25/(0.95*40),0)-IF(E26=0,IF(E25=1,IF(D26=1,30,40)*0.18/(2*40),0),0)-IF(E26=1,IF(E25=0,IF(D26=1,30,40)*0.18/(2*40),0),0) | N26: 0.15 | O26: =K26*N26 | P26: =IF(E26=0,0.3,IF(D26=1,IF(C26>=Params!$B$13-3,IF(C26<Params!$B$13,Params!$B$20,0.3),0.3),IF(C26>=Params!$B$15-3,IF(C26<Params!$B$15,Params!$B$21,0.3),0.3)))
A27: 24 | B27: 01/01 | C27: 23 | D27: 0 | E27: =IF(D27=1, IF(OR(C27<10, C27>=15),1,0), IF(OR(C27<7, C27>=18),1,0)) | F27: 4.137 | G27: =0*8 | H27: =F27-G27 | I27: =IF(E27=0,"Fora",IF(E26=0,"Carg xar",IF(H27<0,IF(M27<0.9,"Carg FV","Stby"),IF(M27>P27,"V2H",IF(M27<0.9,"Carg xar","Stby"))))) | J27: =IF(OR(I27="Carg FV",I27="Carg xar"),MIN(IF(I27="Carg FV",ABS(H27),7.4),7.4,MAX(0,(0.9-M27)*40)*0.95),0) | K27: =IF(I27="V2H",MIN(MAX(0,H27),7.4,MAX(0,(M27-P27)*40)*0.95),0) | L27: =IF(E27=0,0,MAX(0,H27-K27)) | M27: =M26+J26/40-IF(I26="V2H",K26/(0.95*40),0)-IF(E27=0,IF(E26=1,IF(D27=1,30,40)*0.18/(2*40),0),0)-IF(E27=1,IF(E26=0,IF(D27=1,30,40)*0.18/(2*40),0),0) | N27: 0.15 | O27: =K27*N27 | P27: =IF(E27=0,0.3,IF(D27=1,IF(C27>=Params!$B$13-3,IF(C27<Params!$B$13,Params!$B$20,0.3),0.3),IF(C27>=Params!$B$15-3,IF(C27<Params!$B$15,Params!$B$21,0.3),0.3)))
A28: 25 | B28: 02/01 | C28: 0 | D28: 0 | E28: =IF(D28=1, IF(OR(C28<10, C28>=15),1,0), IF(OR(C28<7, C28>=18),1,0)) | F28: 4.275 | G28: =0*8 | H28: =F28-G28 | I28: =IF(E28=0,"Fora",IF(E27=0,"Carg xar",IF(H28<0,IF(M28<0.9,"Carg FV","Stby"),IF(M28>P28,"V2H",IF(M28<0.9,"Carg xar","Stby"))))) | J28: =IF(OR(I28="Carg FV",I28="Carg xar"),MIN(IF(I28="Carg FV",ABS(H28),7.4),7.4,MAX(0,(0.9-M28)*40)*0.95),0) | K28: =IF(I28="V2H",MIN(MAX(0,H28),7.4,MAX(0,(M28-P28)*40)*0.95),0) | L28: =IF(E28=0,0,MAX(0,H28-K28)) | M28: =M27+J27/40-IF(I27="V2H",K27/(0.95*40),0)-IF(E28=0,IF(E27=1,IF(D28=1,30,40)*0.18/(2*40),0),0)-IF(E28=1,IF(E27=0,IF(D28=1,30,40)*0.18/(2*40),0),0) | N28: 0.09 | O28: =K28*N28 | P28: =IF(E28=0,0.3,IF(D28=1,IF(C28>=Params!$B$13-3,IF(C28<Params!$B$13,Params!$B$20,0.3),0.3),IF(C28>=Params!$B$15-3,IF(C28<Params!$B$15,Params!$B$21,0.3),0.3)))
A29: 26 | B29: 02/01 | C29: 1 | D29: 0 | E29: =IF(D29=1, IF(OR(C29<10, C29>=15),1,0), IF(OR(C29<7, C29>=18),1,0)) | F29: 3.708 | G29: =0*8 | H29: =F29-G29 | I29: =IF(E29=0,"Fora",IF(E28=0,"Carg xar",IF(H29<0,IF(M29<0.9,"Carg FV","Stby"),IF(M29>P29,"V2H",IF(M29<0.9,"Carg xar","Stby"))))) | J29: =IF(OR(I29="Carg FV",I29="Carg xar"),MIN(IF(I29="Carg FV",ABS(H29),7.4),7.4,MAX(0,(0.9-M29)*40)*0.95),0) | K29: =IF(I29="V2H",MIN(MAX(0,H29),7.4,MAX(0,(M29-P29)*40)*0.95),0) | L29: =IF(E29=0,0,MAX(0,H29-K29)) | M29: =M28+J28/40-IF(I28="V2H",K28/(0.95*40),0)-IF(E29=0,IF(E28=1,IF(D29=1,30,40)*0.18/(2*40),0),0)-IF(E29=1,IF(E28=0,IF(D29=1,30,40)*0.18/(2*40),0),0) | N29: 0.09 | O29: =K29*N29 | P29: =IF(E29=0,0.3,IF(D29=1,IF(C29>=Params!$B$13-3,IF(C29<Params!$B$13,Params!$B$20,0.3),0.3),IF(C29>=Params!$B$15-3,IF(C29<Params!$B$15,Params!$B$21,0.3),0.3)))
A30: 27 | B30: 02/01 | C30: 2 | D30: 0 | E30: =IF(D30=1, IF(OR(C30<10, C30>=15),1,0), IF(OR(C30<7, C30>=18),1,0)) | F30: 3.92 | G30: =0*8 | H30: =F30-G30 | I30: =IF(E30=0,"Fora",IF(E29=0,"Carg xar",IF(H30<0,IF(M30<0.9,"Carg FV","Stby"),IF(M30>P30,"V2H",IF(M30<0.9,"Carg xar","Stby"))))) | J30: =IF(OR(I30="Carg FV",I30="Carg xar"),MIN(IF(I30="Carg FV",ABS(H30),7.4),7.4,MAX(0,(0.9-M30)*40)*0.95),0) | K30: =IF(I30="V2H",MIN(MAX(0,H30),7.4,MAX(0,(M30-P30)*40)*0.95),0) | L30: =IF(E30=0,0,MAX(0,H30-K30)) | M30: =M29+J29/40-IF(I29="V2H",K29/(0.95*40),0)-IF(E30=0,IF(E29=1,IF(D30=1,30,40)*0.18/(2*40),0),0)-IF(E30=1,IF(E29=0,IF(D30=1,30,40)*0.18/(2*40),0),0) | N30: 0.09 | O30: =K30*N30 | P30: =IF(E30=0,0.3,IF(D30=1,IF(C30>=Params!$B$13-3,IF(C30<Params!$B$13,Params!$B$20,0.3),0.3),IF(C30>=Params!$B$15-3,IF(C30<Params!$B$15,Params!$B$21,0.3),0.3)))
A31: 28 | B31: 02/01 | C31: 3 | D31: 0 | E31: =IF(D31=1, IF(OR(C31<10, C31>=15),1,0), IF(OR(C31<7, C31>=18),1,0)) | F31: 4.764 | G31: =0*8 | H31: =F31-G31 | I31: =IF(E31=0,"Fora",IF(E30=0,"Carg xar",IF(H31<0,IF(M31<0.9,"Carg FV","Stby"),IF(M31>P31,"V2H",IF(M31<0.9,"Carg xar","Stby"))))) | J31: =IF(OR(I31="Carg FV",I31="Carg xar"),MIN(IF(I31="Carg FV",ABS(H31),7.4),7.4,MAX(0,(0.9-M31)*40)*0.95),0) | K31: =IF(I31="V2H",MIN(MAX(0,H31),7.4,MAX(0,(M31-P31)*40)*0.95),0) | L31: =IF(E31=0,0,MAX(0,H31-K31)) | M31: =M30+J30/40-IF(I30="V2H",K30/(0.95*40),0)-IF(E31=0,IF(E30=1,IF(D31=1,30,40)*0.18/(2*40),0),0)-IF(E31=1,IF(E30=0,IF(D31=1,30,40)*0.18/(2*40),0),0) | N31: 0.09 | O31: =K31*N31 | P31: =IF(E31=0,0.3,IF(D31=1,IF(C31>=Params!$B$13-3,IF(C31<Params!$B$13,Params!$B$20,0.3),0.3),IF(C31>=Params!$B$15-3,IF(C31<Params!$B$15,Params!$B$21,0.3),0.3)))
A32: 29 | B32: 02/01 | C32: 4 | D32: 0 | E32: =IF(D32=1, IF(OR(C32<10, C32>=15),1,0), IF(OR(C32<7, C32>=18),1,0)) | F32: 4.182 | G32: =0*8 | H32: =F32-G32 | I32: =IF(E32=0,"Fora",IF(E31=0,"Carg xar",IF(H32<0,IF(M32<0.9,"Carg FV","Stby"),IF(M32>P32,"V2H",IF(M32<0.9,"Carg xar","Stby"))))) | J32: =IF(OR(I32="Carg FV",I32="Carg xar"),MIN(IF(I32="Carg FV",ABS(H32),7.4),7.4,MAX(0,(0.9-M32)*40)*0.95),0) | K32: =IF(I32="V2H",MIN(MAX(0,H32),7.4,MAX(0,(M32-P32)*40)*0.95),0) | L32: =IF(E32=0,0,MAX(0,H32-K32)) | M32: =M31+J31/40-IF(I31="V2H",K31/(0.95*40),0)-IF(E32=0,IF(E31=1,IF(D32=1,30,40)*0.18/(2*40),0),0)-IF(E32=1,IF(E31=0,IF(D32=1,30,40)*0.18/(2*40),0),0) | N32: 0.09 | O32: =K32*N32 | P32: =IF(E32=0,0.3,IF(D32=1,IF(C32>=Params!$B$13-3,IF(C32<Params!$B$13,Params!$B$20,0.3),0.3),IF(C32>=Params!$B$15-3,IF(C32<Params!$B$15,Params!$B$21,0.3),0.3)))
... A35: 32 | B35: 02/01 | C35: 7 | D35: 0 | E35: =IF(D35=1, IF(OR(C35<10, C35>=15),1,0), IF(OR(C35<7, C35>=18),1,0)) | F35: 4.266 | G35: =0*8 | H35: =F35-G35 | I35: =IF(E35=0,"Fora",IF(E34=0,"Carg xar",IF(H35<0,IF(M35<0.9,"Carg FV","Stby"),IF(M35>P35,"V2H",IF(M35<0.9,"Carg xar","Stby"))))) | J35: =IF(OR(I35="Carg FV",I35="Carg xar"),MIN(IF(I35="Carg FV",ABS(H35),7.4),7.4,MAX(0,(0.9-M35)*40)*0.95),0) | K35: =IF(I35="V2H",MIN(MAX(0,H35),7.4,MAX(0,(M35-P35)*40)*0.95),0) | L35: =IF(E35=0,0,MAX(0,H35-K35)) | M35: =M34+J34/40-IF(I34="V2H",K34/(0.95*40),0)-IF(E35=0,IF(E34=1,IF(D35=1,30,40)*0.18/(2*40),0),0)-IF(E35=1,IF(E34=0,IF(D35=1,30,40)*0.18/(2*40),0),0) | N35: 0.09 | O35: =K35*N35 | P35: =IF(E35=0,0.3,IF(D35=1,IF(C35>=Params!$B$13-3,IF(C35<Params!$B$13,Params!$B$20,0.3),0.3),IF(C35>=Params!$B$15-3,IF(C35<Params!$B$15,Params!$B$21,0.3),0.3)))
A36: 33 | B36: 02/01 | C36: 8 | D36: 0 | E36: =IF(D36=1, IF(OR(C36<10, C36>=15),1,0), IF(OR(C36<7, C36>=18),1,0)) | F36: 4.371 | G36: =0.05*8 | H36: =F36-G36 | I36: =IF(E36=0,"Fora",IF(E35=0,"Carg xar",IF(H36<0,IF(M36<0.9,"Carg FV","Stby"),IF(M36>P36,"V2H",IF(M36<0.9,"Carg xar","Stby"))))) | J36: =IF(OR(I36="Carg FV",I36="Carg xar"),MIN(IF(I36="Carg FV",ABS(H36),7.4),7.4,MAX(0,(0.9-M36)*40)*0.95),0) | K36: =IF(I36="V2H",MIN(MAX(0,H36),7.4,MAX(0,(M36-P36)*40)*0.95),0) | L36: =IF(E36=0,0,MAX(0,H36-K36)) | M36: =M35+J35/40-IF(I35="V2H",K35/(0.95*40),0)-IF(E36=0,IF(E35=1,IF(D36=1,30,40)*0.18/(2*40),0),0)-IF(E36=1,IF(E35=0,IF(D36=1,30,40)*0.18/(2*40),0),0) | N36: 0.15 | O36: =K36*N36 | P36: =IF(E36=0,0.3,IF(D36=1,IF(C36>=Params!$B$13-3,IF(C36<Params!$B$13,Params!$B$20,0.3),0.3),IF(C36>=Params!$B$15-3,IF(C36<Params!$B$15,Params!$B$21,0.3),0.3)))
A37: 34 | B37: 02/01 | C37: 9 | D37: 0 | E37: =IF(D37=1, IF(OR(C37<10, C37>=15),1,0), IF(OR(C37<7, C37>=18),1,0)) | F37: 1.596 | G37: =0.18*8 | H37: =F37-G37 | I37: =IF(E37=0,"Fora",IF(E36=0,"Carg xar",IF(H37<0,IF(M37<0.9,"Carg FV","Stby"),IF(M37>P37,"V2H",IF(M37<0.9,"Carg xar","Stby"))))) | J37: =IF(OR(I37="Carg FV",I37="Carg xar"),MIN(IF(I37="Carg FV",ABS(H37),7.4),7.4,MAX(0,(0.9-M37)*40)*0.95),0) | K37: =IF(I37="V2H",MIN(MAX(0,H37),7.4,MAX(0,(M37-P37)*40)*0.95),0) | L37: =IF(E37=0,0,MAX(0,H37-K37)) | M37: =M36+J36/40-IF(I36="V2H",K36/(0.95*40),0)-IF(E37=0,IF(E36=1,IF(D37=1,30,40)*0.18/(2*40),0),0)-IF(E37=1,IF(E36=0,IF(D37=1,30,40)*0.18/(2*40),0),0) | N37: 0.15 | O37: =K37*N37 | P37: =IF(E37=0,0.3,IF(D37=1,IF(C37>=Params!$B$13-3,IF(C37<Params!$B$13,Params!$B$20,0.3),0.3),IF(C37>=Params!$B$15-3,IF(C37<Params!$B$15,Params!$B$21,0.3),0.3)))
A38: 35 | B38: 02/01 | C38: 10 | D38: 0 | E38: =IF(D38=1, IF(OR(C38<10, C38>=15),1,0), IF(OR(C38<7, C38>=18),1,0)) | F38: 1.336 | G38: =0.38*8 | H38: =F38-G38 | I38: =IF(E38=0,"Fora",IF(E37=0,"Carg xar",IF(H38<0,IF(M38<0.9,"Carg FV","Stby"),IF(M38>P38,"V2H",IF(M38<0.9,"Carg xar","Stby"))))) | J38: =IF(OR(I38="Carg FV",I38="Carg xar"),MIN(IF(I38="Carg FV",ABS(H38),7.4),7.4,MAX(0,(0.9-M38)*40)*0.95),0) | K38: =IF(I38="V2H",MIN(MAX(0,H38),7.4,MAX(0,(M38-P38)*40)*0.95),0) | L38: =IF(E38=0,0,MAX(0,H38-K38)) | M38: =M37+J37/40-IF(I37="V2H",K37/(0.95*40),0)-IF(E38=0,IF(E37=1,IF(D38=1,30,40)*0.18/(2*40),0),0)-IF(E38=1,IF(E37=0,IF(D38=1,30,40)*0.18/(2*40),0),0) | N38: 0.2 | O38: =K38*N38 | P38: =IF(E38=0,0.3,IF(D38=1,IF(C38>=Params!$B$13-3,IF(C38<Params!$B$13,Params!$B$20,0.3),0.3),IF(C38>=Params!$B$15-3,IF(C38<Params!$B$15,Params!$B$21,0.3),0.3)))
A39: 36 | B39: 02/01 | C39: 11 | D39: 0 | E39: =IF(D39=1, IF(OR(C39<10, C39>=15),1,0), IF(OR(C39<7, C39>=18),1,0)) | F39: 0 | G39: =0.52*8 | H39: =F39-G39 | I39: =IF(E39=0,"Fora",IF(E38=0,"Carg xar",IF(H39<0,IF(M39<0.9,"Carg FV","Stby"),IF(M39>P39,"V2H",IF(M39<0.9,"Carg xar","Stby"))))) | J39: =IF(OR(I39="Carg FV",I39="Carg xar"),MIN(IF(I39="Carg FV",ABS(H39),7.4),7.4,MAX(0,(0.9-M39)*40)*0.95),0) | K39: =IF(I39="V2H",MIN(MAX(0,H39),7.4,MAX(0,(M39-P39)*40)*0.95),0) | L39: =IF(E39=0,0,MAX(0,H39-K39)) | M39: =M38+J38/40-IF(I38="V2H",K38/(0.95*40),0)-IF(E39=0,IF(E38=1,IF(D39=1,30,40)*0.18/(2*40),0),0)-IF(E39=1,IF(E38=0,IF(D39=1,30,40)*0.18/(2*40),0),0) | N39: 0.2 | O39: =K39*N39 | P39: =IF(E39=0,0.3,IF(D39=1,IF(C39>=Params!$B$13-3,IF(C39<Params!$B$13,Params!$B$20,0.3),0.3),IF(C39>=Params!$B$15-3,IF(C39<Params!$B$15,Params!$B$21,0.3),0.3)))
A40: 37 | B40: 02/01 | C40: 12 | D40: 0 | E40: =IF(D40=1, IF(OR(C40<10, C40>=15),1,0), IF(OR(C40<7, C40>=18),1,0)) | F40: 2.211 | G40: =0.58*8 | H40: =F40-G40 | I40: =IF(E40=0,"Fora",IF(E39=0,"Carg xar",IF(H40<0,IF(M40<0.9,"Carg FV","Stby"),IF(M40>P40,"V2H",IF(M40<0.9,"Carg xar","Stby"))))) | J40: =IF(OR(I40="Carg FV",I40="Carg xar"),MIN(IF(I40="Carg FV",ABS(H40),7.4),7.4,MAX(0,(0.9-M40)*40)*0.95),0) | K40: =IF(I40="V2H",MIN(MAX(0,H40),7.4,MAX(0,(M40-P40)*40)*0.95),0) | L40: =IF(E40=0,0,MAX(0,H40-K40)) | M40: =M39+J39/40-IF(I39="V2H",K39/(0.95*40),0)-IF(E40=0,IF(E39=1,IF(D40=1,30,40)*0.18/(2*40),0),0)-IF(E40=1,IF(E39=0,IF(D40=1,30,40)*0.18/(2*40),0),0) | N40: 0.2 | O40: =K40*N40 | P40: =IF(E40=0,0.3,IF(D40=1,IF(C40>=Params!$B$13-3,IF(C40<Params!$B$13,Params!$B$20,0.3),0.3),IF(C40>=Params!$B$15-3,IF(C40<Params!$B$15,Params!$B$21,0.3),0.3)))
A41: 38 | B41: 02/01 | C41: 13 | D41: 0 | E41: =IF(D41=1, IF(OR(C41<10, C41>=15),1,0), IF(OR(C41<7, C41>=18),1,0)) | F41: 0 | G41: =0.55*8 | H41: =F41-G41 | I41: =IF(E41=0,"Fora",IF(E40=0,"Carg xar",IF(H41<0,IF(M41<0.9,"Carg FV","Stby"),IF(M41>P41,"V2H",IF(M41<0.9,"Carg xar","Stby"))))) | J41: =IF(OR(I41="Carg FV",I41="Carg xar"),MIN(IF(I41="Carg FV",ABS(H41),7.4),7.4,MAX(0,(0.9-M41)*40)*0.95),0) | K41: =IF(I41="V2H",MIN(MAX(0,H41),7.4,MAX(0,(M41-P41)*40)*0.95),0) | L41: =IF(E41=0,0,MAX(0,H41-K41)) | M41: =M40+J40/40-IF(I40="V2H",K40/(0.95*40),0)-IF(E41=0,IF(E40=1,IF(D41=1,30,40)*0.18/(2*40),0),0)-IF(E41=1,IF(E40=0,IF(D41=1,30,40)*0.18/(2*40),0),0) | N41: 0.2 | O41: =K41*N41 | P41: =IF(E41=0,0.3,IF(D41=1,IF(C41>=Params!$B$13-3,IF(C41<Params!$B$13,Params!$B$20,0.3),0.3),IF(C41>=Params!$B$15-3,IF(C41<Params!$B$15,Params!$B$21,0.3),0.3)))
A42: 39 | B42: 02/01 | C42: 14 | D42: 0 | E42: =IF(D42=1, IF(OR(C42<10, C42>=15),1,0), IF(OR(C42<7, C42>=18),1,0)) | F42: 0 | G42: =0.42*8 | H42: =F42-G42 | I42: =IF(E42=0,"Fora",IF(E41=0,"Carg xar",IF(H42<0,IF(M42<0.9,"Carg FV","Stby"),IF(M42>P42,"V2H",IF(M42<0.9,"Carg xar","Stby"))))) | J42: =IF(OR(I42="Carg FV",I42="Carg xar"),MIN(IF(I42="Carg FV",ABS(H42),7.4),7.4,MAX(0,(0.9-M42)*40)*0.95),0) | K42: =IF(I42="V2H",MIN(MAX(0,H42),7.4,MAX(0,(M42-P42)*40)*0.95),0) | L42: =IF(E42=0,0,MAX(0,H42-K42)) | M42: =M41+J41/40-IF(I41="V2H",K41/(0.95*40),0)-IF(E42=0,IF(E41=1,IF(D42=1,30,40)*0.18/(2*40),0),0)-IF(E42=1,IF(E41=0,IF(D42=1,30,40)*0.18/(2*40),0),0) | N42: 0.15 | O42: =K42*N42 | P42: =IF(E42=0,0.3,IF(D42=1,IF(C42>=Params!$B$13-3,IF(C42<Params!$B$13,Params!$B$20,0.3),0.3),IF(C42>=Params!$B$15-3,IF(C42<Params!$B$15,Params!$B$21,0.3),0.3)))
A43: 40 | B43: 02/01 | C43: 15 | D43: 0 | E43: =IF(D43=1, IF(OR(C43<10, C43>=15),1,0), IF(OR(C43<7, C43>=18),1,0)) | F43: 0.118 | G43: =0.22*8 | H43: =F43-G43 | I43: =IF(E43=0,"Fora",IF(E42=0,"Carg xar",IF(H43<0,IF(M43<0.9,"Carg FV","Stby"),IF(M43>P43,"V2H",IF(M43<0.9,"Carg xar","Stby"))))) | J43: =IF(OR(I43="Carg FV",I43="Carg xar"),MIN(IF(I43="Carg FV",ABS(H43),7.4),7.4,MAX(0,(0.9-M43)*40)*0.95),0) | K43: =IF(I43="V2H",MIN(MAX(0,H43),7.4,MAX(0,(M43-P43)*40)*0.95),0) | L43: =IF(E43=0,0,MAX(0,H43-K43)) | M43: =M42+J42/40-IF(I42="V2H",K42/(0.95*40),0)-IF(E43=0,IF(E42=1,IF(D43=1,30,40)*0.18/(2*40),0),0)-IF(E43=1,IF(E42=0,IF(D43=1,30,40)*0.18/(2*40),0),0) | N43: 0.15 | O43: =K43*N43 | P43: =IF(E43=0,0.3,IF(D43=1,IF(C43>=Params!$B$13-3,IF(C43<Params!$B$13,Params!$B$20,0.3),0.3),IF(C43>=Params!$B$15-3,IF(C43<Params!$B$15,Params!$B$21,0.3),0.3)))
...

Sheet Resum
A1: RESUM ANUAL — SIMULACIÓ 8760h (v7)
A3: Mes | B3: E_V2H kWh | C3: E_xarxa kWh | D3: Estalvi € | E3: Consum llar kWh
A4: Gener | B4: =SUM('Sim8760'!K4:K747) | C4: =SUM('Sim8760'!L4:L747) | D4: =SUM('Sim8760'!O4:O747) | E4: =SUM('Sim8760'!F4:F747)
A5: Febrer | B5: =SUM('Sim8760'!K748:K1419) | C5: =SUM('Sim8760'!L748:L1419) | D5: =SUM('Sim8760'!O748:O1419) | E5: =SUM('Sim8760'!F748:F1419)
A6: Març | B6: =SUM('Sim8760'!K1420:K2163) | C6: =SUM('Sim8760'!L1420:L2163) | D6: =SUM('Sim8760'!O1420:O2163) | E6: =SUM('Sim8760'!F1420:F2163)
A7: Abril | B7: =SUM('Sim8760'!K2164:K2883) | C7: =SUM('Sim8760'!L2164:L2883) | D7: =SUM('Sim8760'!O2164:O2883) | E7: =SUM('Sim8760'!F2164:F2883)
A8: Maig | B8: =SUM('Sim8760'!K2884:K3627) | C8: =SUM('Sim8760'!L2884:L3627) | D8: =SUM('Sim8760'!O2884:O3627) | E8: =SUM('Sim8760'!F2884:F3627)
A9: Juny | B9: =SUM('Sim8760'!K3628:K4347) | C9: =SUM('Sim8760'!L3628:L4347) | D9: =SUM('Sim8760'!O3628:O4347) | E9: =SUM('Sim8760'!F3628:F4347)
A10: Juliol | B10: =SUM('Sim8760'!K4348:K5091) | C10: =SUM('Sim8760'!L4348:L5091) | D10: =SUM('Sim8760'!O4348:O5091) | E10: =SUM('Sim8760'!F4348:F5091)
A11: Agost | B11: =SUM('Sim8760'!K5092:K5835) | C11: =SUM('Sim8760'!L5092:L5835) | D11: =SUM('Sim8760'!O5092:O5835) | E11: =SUM('Sim8760'!F5092:F5835)
A12: Set. | B12: =SUM('Sim8760'!K5836:K6555) | C12: =SUM('Sim8760'!L5836:L6555) | D12: =SUM('Sim8760'!O5836:O6555) | E12: =SUM('Sim8760'!F5836:F6555)
A13: Octubre | B13: =SUM('Sim8760'!K6556:K7299) | C13: =SUM('Sim8760'!L6556:L7299) | D13: =SUM('Sim8760'!O6556:O7299) | E13: =SUM('Sim8760'!F6556:F7299)
A14: Nov. | B14: =SUM('Sim8760'!K7300:K8019) | C14: =SUM('Sim8760'!L7300:L8019) | D14: =SUM('Sim8760'!O7300:O8019) | E14: =SUM('Sim8760'!F7300:F8019)
A15: Desembre | B15: =SUM('Sim8760'!K8020:K8763) | C15: =SUM('Sim8760'!L8020:L8763) | D15: =SUM('Sim8760'!O8020:O8763) | E15: =SUM('Sim8760'!F8020:F8763)
A16: TOTAL ANUAL | B16: =SUM(B4:B15) | C16: =SUM(C4:C15) | D16: =SUM(D4:D15) | E16: =SUM(E4:E15)
A18: INDICADORS CLAU
A19: Estalvi anual: | B19: =D16 | C19: €/any
A20: E_V2H anual: | B20: =B16 | C20: kWh/any
A21: E_xarxa anual: | B21: =C16 | C21: kWh/any
A22: Consum llar anual: | B22: =E16 | C22: kWh/any
A23: Autoconsum V2H: | B23: =IF(B16+C16>0,B16/(B16+C16),0) | C23: %
A24: EFC V2H anuals: | B24: =B16/(2*40) | C24: cicles/any
A25: Cost carregador (est.): | B25: 4000 | C25: €
A26: Payback simple: | B26: =IF(B19>0,B25/B19,"—") | C26: anys
A27: SOC final any: | B27: ='Sim8760'!M8763 | C27: %
